Workbook

Sheet 说明&简化逻辑
A1: Load Profile simplified intervention logic / 简化干预逻辑
A2: Purpose / 目的 | B2: Build a Germany-focused simulator that keeps Annual kWh + Monthly share + 24h share. No 8,760 hourly expansion.
A4: Factor / 因子 | B4: Options / 选项 | C4: Simplified logic (CN) | D4: Simplified logic (EN) | E4: Affects / 影响维度 | F4: Germany definition / 德国定义 | G4: Notes / 备注
A5: 居住占用模式 / Daytime Occupancy | B5: Mostly away / WFH / Always home | C5: 仅影响24小时分布，不改变年用电量和月度占比。09:00–17:00按选项系数调整（离家较多×0.6；WFH×1.4；一直有人在家×1.2），其余小时保持1.0，然后对全天24小时重新归一化。 | D5: Only changes the 24-hour shape; annual kWh and monthly share stay unchanged. Hours 09:00–17:00 are multiplied by the selected factor (mostly away ×0.6; WFH ×1.4; always home ×1.2), all other hours stay at 1.0, then the profile is normalized back to 100%. | E5: 24h shape only | F5: Daytime window = 09:00–17:00 | G5: Best for distinguishing day-heavy vs night-heavy households.
A6: 供暖/制冷系统 / Heating & Cooling System | B6: None / AC / Electric heating / Heat pump | C6: 决定是否启用冷暖季节修正，以及是否增加额外年电量。空调只重分配冷季月份和下午峰值，不增加年电量；电采暖和热泵会按系统基准热负荷增加年电量。 | D6: Controls whether cooling/heating seasonal reshaping is active and whether extra annual kWh is added. Air conditioning only redistributes load toward cooling months and cooling peak hours; it does not add annual kWh. Electric heating and heat pumps add extra annual kWh based on a base thermal load. | E6: Annual + Monthly + 24h | F6: Cooling season = Jun–Aug; Heating season = Oct–Apr | G6: Base thermal load used in this file: electric heating 3,000 kWh; heat pump 2,000 kWh.
A7: 冷暖使用强度 / Heating & Cooling Usage | B7: Low / Medium / High / Very high | C7: 使用强度决定三类系数：①年电量增量倍率；②冷暖季月份加强倍率；③冷暖峰时段加强倍率。强度越高，季节性和峰时段越明显。 | D7: Usage level controls three coefficient families: (1) annual extra-kWh multiplier, (2) seasonal month multipliers, and (3) peak-hour multipliers. Higher intensity creates stronger seasonal and within-day concentration. | E7: Annual + Monthly + 24h | F7: Applied only when a heating/cooling system is selected | G7: This workbook uses simplified Germany demo coefficients, documented below.
A8: 电动车年里程 / EV Annual Driving | B8: 0 / 5k / 10k / 15k / 20k / 25k+ km | C8: 按里程 × 0.18 kWh/km 计算电动车新增年电量。新增电量默认平均分摊到12个月，因此会轻微拉平月度占比。 | D8: EV annual kWh is calculated as mileage × 0.18 kWh/km. The added EV kWh is spread evenly across 12 months by default, which slightly flattens the monthly share pattern. | E8: Annual + Monthly | F8: EV efficiency = 0.18 kWh/km | G8: No direct 24h impact until a charging pattern is selected.
A9: EV充电习惯 / EV Charging Pattern | B9: Overnight / Mixed / Daytime / Solar-optimized | C9: 不改变年电量和月度占比，只影响24小时分布。系统会把EV日均电量叠加到相应时段后重新归一化。Solar-optimized在本文件中采用简化逻辑：80%按白天光伏代理曲线分配，20%回落到夜间。 | D9: Does not change annual kWh or monthly shares; only changes the 24-hour shape. The EV daily kWh is added to the selected charging window and then normalized. In this workbook, Solar-optimized is simplified to 80% following a daytime PV proxy shape and 20% shifted to overnight hours. | E9: 24h shape only | F9: Overnight = 22:00–05:00; Daytime = 10:00–15:00 | G9: This is an average-day representation, not a smart-charging dispatch model.
A12: Simplified coefficients / 简化系数
A13: Type | B13: Option | C13: CN summary | D13: EN summary | E13: Key values | F13: Applies to | G13: Comment
A14: Occupancy | B14: Mostly away during the day | C14: 白天系数0.6 | D14: Daytime factor 0.6 | E14: 09–17 ×0.6 | F14: 24h | G14: Night-heavy household
A15: Occupancy | B15: Working from home | C15: 白天系数1.4 | D15: Daytime factor 1.4 | E15: 09–17 ×1.4 | F15: 24h | G15: Day-heavy household
A16: Occupancy | B16: Someone always at home | C16: 白天系数1.2 | D16: Daytime factor 1.2 | E16: 09–17 ×1.2 | F16: 24h | G16: Moderately day-heavy
A17: Usage | B17: Low | C17: 低强度 | D17: Low intensity | E17: Annual ×0.7; Cool month ×1.05; Heat month ×1.08 | F17: Annual+Monthly+24h | G17: Demo simplification
A18: Usage | B18: Medium | C18: 中等强度 | D18: Medium intensity | E18: Annual ×1.0; Cool month ×1.10; Heat month ×1.15 | F18: Annual+Monthly+24h | G18: Default
A19: Usage | B19: High | C19: 高强度 | D19: High intensity | E19: Annual ×1.3; Cool month ×1.20; Heat month ×1.25 | F19: Annual+Monthly+24h | G19: Demo simplification
A20: Usage | B20: Very high | C20: 很高强度 | D20: Very high intensity | E20: Annual ×1.6; Cool month ×1.35; Heat month ×1.40 | F20: Annual+Monthly+24h | G20: Demo simplification
A21: Peak | B21: Cooling peak | C21: 冷峰时段 | D21: Cooling peak hours | E21: 14–19 × [1.10 / 1.20 / 1.35 / 1.50] | F21: 24h | G21: By usage level
A22: Peak | B22: Heating peak | C22: 热峰时段 | D22: Heating peak hours | E22: 06–09 & 18–22 × [1.08 / 1.15 / 1.25 / 1.40] | F22: 24h | G22: By usage level
A23: EV | B23: Mileage to kWh | C23: 按里程转电量 | D23: Mileage converted to kWh | E23: km × 0.18 | F23: Annual+Monthly | G23: Flat monthly add-on

Sheet DE_Base_Profile
A1: Germany Base Profile (based on uploaded file)
A2: Source | B2: https://www.bdew.de/energie/standardlastprofile-strom/
A3: Model note | B3: This workbook keeps the structure as Annual kWh + Monthly share + 24h share; no 8,760 expansion.
A5: Month | B5: Base Monthly Share | C5: Base kWh @ 3,500 | D5: Cooling Season Flag | E5: Heating Season Flag | F5: Comment | H5: Hour | I5: Base 24h Share | J5: Daytime Flag (09-17) | K5: Cooling Peak Flag (14-19) | L5: Heating Peak Flag (06-09 & 18-22) | M5: Solar PV Proxy | N5: Mostly overnight | O5: Mixed day and night | P5: Mostly daytime | Q5: Solar-optimized charging
A6: 1月 | B6: 0.0789 | C6: =3500*B6 -> 276.15 | D6: 0 | E6: 1 | F6: Heating season | H6: 0 | I6: 0.0301 | J6: 0 | K6: 0 | L6: 0 | M6: 0 | N6: 0.125 | O6: 0.075 | P6: 0 | Q6: 0.025
A7: 2月 | B7: 0.0791 | C7: =3500*B7 -> 276.85 | D7: 0 | E7: 1 | F7: Heating season | H7: 1 | I7: 0.0258 | J7: 0 | K7: 0 | L7: 0 | M7: 0 | N7: 0.125 | O7: 0.075 | P7: 0 | Q7: 0.025
A8: 3月 | B8: 0.0773 | C8: =3500*B8 -> 270.55 | D8: 0 | E8: 1 | F8: Heating season | H8: 2 | I8: 0.0239 | J8: 0 | K8: 0 | L8: 0 | M8: 0 | N8: 0.125 | O8: 0.075 | P8: 0 | Q8: 0.025
A9: 4月 | B9: 0.0822 | C9: =3500*B9 -> 287.7 | D9: 0 | E9: 1 | F9: Heating season | H9: 3 | I9: 0.0232 | J9: 0 | K9: 0 | L9: 0 | M9: 0 | N9: 0.125 | O9: 0.075 | P9: 0 | Q9: 0.025
A10: 5月 | B10: 0.0839 | C10: =3500*B10 -> 293.65 | D10: 0 | E10: 0 | F10: Shoulder month | H10: 4 | I10: 0.0236 | J10: 0 | K10: 0 | L10: 0 | M10: 0 | N10: 0.125 | O10: 0.075 | P10: 0 | Q10: 0.025
A11: 6月 | B11: 0.0876 | C11: =3500*B11 -> 306.6 | D11: 1 | E11: 0 | F11: Cooling season | H11: 5 | I11: 0.0252 | J11: 0 | K11: 0 | L11: 0 | M11: 0 | N11: 0.125 | O11: 0.075 | P11: 0 | Q11: 0.025
A12: 7月 | B12: 0.0917 | C12: =3500*B12 -> 320.95 | D12: 1 | E12: 0 | F12: Cooling season | H12: 6 | I12: 0.03 | J12: 0 | K12: 0 | L12: 1 | M12: 0 | N12: 0 | O12: 0 | P12: 0 | Q12: 0
A13: 8月 | B13: 0.0887 | C13: =3500*B13 -> 310.45 | D13: 1 | E13: 0 | F13: Cooling season | H13: 7 | I13: 0.0358 | J13: 0 | K13: 0 | L13: 1 | M13: 0 | N13: 0 | O13: 0 | P13: 0 | Q13: 0
A14: 9月 | B14: 0.0853 | C14: =3500*B14 -> 298.55 | D14: 0 | E14: 0 | F14: Shoulder month | H14: 8 | I14: 0.041 | J14: 0 | K14: 0 | L14: 1 | M14: 0 | N14: 0 | O14: 0 | P14: 0 | Q14: 0
A15: 10月 | B15: 0.0838 | C15: =3500*B15 -> 293.3 | D15: 0 | E15: 1 | F15: Heating season | H15: 9 | I15: 0.0446 | J15: 1 | K15: 0 | L15: 1 | M15: 0.05 | N15: 0 | O15: 0 | P15: 0 | Q15: 0.04
A16: 11月 | B16: 0.0819 | C16: =3500*B16 -> 286.65 | D16: 0 | E16: 1 | F16: Heating season | H16: 10 | I16: 0.0474 | J16: 1 | K16: 0 | L16: 0 | M16: 0.09 | N16: 0 | O16: 0.066666667 | P16: 0.16666667 | Q16: 0.072
A17: 12月 | B17: 0.0796 | C17: =3500*B17 -> 278.6 | D17: 0 | E17: 1 | F17: Heating season | H17: 11 | I17: 0.0518 | J17: 1 | K17: 0 | L17: 0 | M17: 0.13 | N17: 0 | O17: 0.066666667 | P17: 0.16666667 | Q17: 0.104
A18: Total | B18: =SUM(B6:B17) -> 1 | C18: =SUM(C6:C17) -> 3500 | H18: 12 | I18: 0.0513 | J18: 1 | K18: 0 | L18: 0 | M18: 0.16 | N18: 0 | O18: 0.066666667 | P18: 0.16666667 | Q18: 0.128
H19: 13 | I19: 0.0481 | J19: 1 | K19: 0 | L19: 0 | M19: 0.17 | N19: 0 | O19: 0.066666667 | P19: 0.16666667 | Q19: 0.136
H20: 14 | I20: 0.0459 | J20: 1 | K20: 1 | L20: 0 | M20: 0.16 | N20: 0 | O20: 0.066666667 | P20: 0.16666667 | Q20: 0.128
H21: 15 | I21: 0.0454 | J21: 1 | K21: 1 | L21: 0 | M21: 0.13 | N21: 0 | O21: 0.066666667 | P21: 0.16666667 | Q21: 0.104
H22: 16 | I22: 0.0475 | J22: 1 | K22: 1 | L22: 0 | M22: 0.11 | N22: 0 | O22: 0 | P22: 0 | Q22: 0.088
H23: 17 | I23: 0.0535 | J23: 1 | K23: 1 | L23: 0 | M23: 0 | N23: 0 | O23: 0 | P23: 0 | Q23: 0
H24: 18 | I24: 0.0587 | J24: 0 | K24: 1 | L24: 1 | M24: 0 | N24: 0 | O24: 0 | P24: 0 | Q24: 0
H25: 19 | I25: 0.0591 | J25: 0 | K25: 1 | L25: 1 | M25: 0 | N25: 0 | O25: 0 | P25: 0 | Q25: 0
H26: 20 | I26: 0.0556 | J26: 0 | K26: 0 | L26: 1 | M26: 0 | N26: 0 | O26: 0 | P26: 0 | Q26: 0
H27: 21 | I27: 0.0508 | J27: 0 | K27: 0 | L27: 1 | M27: 0 | N27: 0 | O27: 0 | P27: 0 | Q27: 0
H28: 22 | I28: 0.0451 | J28: 0 | K28: 0 | L28: 1 | M28: 0 | N28: 0.125 | O28: 0.075 | P28: 0 | Q28: 0.025
H29: 23 | I29: 0.0366 | J29: 0 | K29: 0 | L29: 0 | M29: 0 | N29: 0.125 | O29: 0.075 | P29: 0 | Q29: 0.025
H30: Total | I30: =SUM(I6:I29) -> 1 | N30: =SUM(N6:N29) -> 1 | O30: =SUM(O6:O29) -> 1 | P30: =SUM(P6:P29) -> 1 | Q30: =SUM(Q6:Q29) -> 1

Sheet DE_Simulator
A1: Germany Load Profile Simulator
A2: Use the drop-down cells in blue. Result = Annual kWh + Monthly share + 24h share, without 8,760 expansion.
A4: Base Annual Consumption (kWh) / 年总用电量 | B4: 3500 | F4: Usage multiplier | G4: =INDEX(DE_Lookups!$E$2:$E$5,MATCH($B$7,DE_Lookups!$D$2:$D$5,0)) -> 1 | I4: Result summary / 结果摘要
A5: Daytime Occupancy / 居住占用模式 | B5: Mostly away during the day | F5: Thermal extra annual kWh | G5: =IF(OR($B$6="Electric heating",$B$6="Heat pump (heating & cooling)"),INDEX(DE_Lookups!$L$2:$L$5,MATCH($B$6,DE_Lookups!$K$2:$K$5,0))*G4,0) -> 0 | I5: Monthly result = reshaped base monthly kWh + thermal extra + flat EV add-on
A6: Heating and Cooling System / 供暖/制冷系统 | B6: No heating or cooling system | F6: EV extra annual kWh | G6: =INDEX(DE_Lookups!$O$2:$O$7,MATCH($B$8,DE_Lookups!$N$2:$N$7,0))*0.18 -> 0 | I6: 24h result = reshaped non-EV daily load + EV daily charging shape
A7: Heating and Cooling Usage / 冷暖使用强度 | B7: Medium | F7: Final annual kWh | G7: =$B$4+$G$5+$G$6 -> 3500 | I7: Solar-optimized charging is simplified to 80% PV proxy + 20% overnight
A8: EV Annual Driving / 电动车年里程 | B8: No electric vehicle | F8: Cooling month multiplier | G8: =INDEX(DE_Lookups!$F$2:$F$5,MATCH($B$7,DE_Lookups!$D$2:$D$5,0)) -> 1.1
A9: EV Charging Pattern / EV充电习惯 | B9: Mostly overnight | F9: Heating month multiplier | G9: =INDEX(DE_Lookups!$G$2:$G$5,MATCH($B$7,DE_Lookups!$D$2:$D$5,0)) -> 1.15
F10: Cooling peak multiplier | G10: =INDEX(DE_Lookups!$H$2:$H$5,MATCH($B$7,DE_Lookups!$D$2:$D$5,0)) -> 1.2
F11: Heating peak multiplier | G11: =INDEX(DE_Lookups!$I$2:$I$5,MATCH($B$7,DE_Lookups!$D$2:$D$5,0)) -> 1.15
A13: Month | B13: Base Share | C13: Base kWh | D13: Seasonal Mult | E13: Reshaped Base kWh | F13: Thermal Weight | G13: Thermal Extra kWh | H13: EV Extra kWh | I13: Final kWh | J13: Final Share | K13: Δ vs Base Share | M13: Hour | N13: Base Share | O13: Occupancy Mult | P13: Peak Mult | Q13: Adj. Non-EV Share | R13: Non-EV kWh/day | S13: EV Share | T13: EV kWh/day | U13: Final kWh/day | V13: Final Share | W13: Δ vs Base Share
A14: 1月 | B14: =DE_Base_Profile!B6 -> 0.0789 | C14: =$B$4*B14 -> 276.15 | D14: =1+IF(OR($B$6="Air conditioning",$B$6="Heat pump (heating & cooling)"),IF(DE_Base_Profile!D6=1,$G$8-1,0),0)+IF(OR($B$6="Electric heating",$B$6="Heat pump (heating & cooling)"),IF(DE_Base_Profile!E6=1,$G$9-1,0),0) -> 1 | E14: =C14*D14 -> 276.15 | F14: =IF($B$6="Electric heating",IF(DE_Base_Profile!E6=1,B14*$G$9,0),IF($B$6="Heat pump (heating & cooling)",IF(DE_Base_Profile!D6=1,B14*$G$8,0)+IF(DE_Base_Profile!E6=1,B14*$G$9,0),0)) -> 0 | G14: =IF(SUM($F$14:$F$25)=0,0,$G$5*F14/SUM($F$14:$F$25)) -> 0 | H14: =$G$6/12 -> 0 | I14: =E14/SUM($E$14:$E$25)*$B$4+G14+H14 -> 276.15 | J14: =I14/$G$7 -> 0.0789 | K14: =J14-B14 -> 0 | M14: 0 | N14: =DE_Base_Profile!I6 -> 0.0301 | O14: =IF(DE_Base_Profile!J6=1,INDEX(DE_Lookups!$B$2:$B$4,MATCH($B$5,DE_Lookups!$A$2:$A$4,0)),1) -> 1 | P14: =IF(OR($B$6="Air conditioning",$B$6="Heat pump (heating & cooling)"),IF(DE_Base_Profile!K6=1,$G$10,1),1)*IF(OR($B$6="Electric heating",$B$6="Heat pump (heating & cooling)"),IF(DE_Base_Profile!L6=1,$G$11,1),1) -> 1 | Q14: =N14*O14*P14 -> 0.0301 | R14: =Q14/SUM($Q$14:$Q$37) -> 0.036449504 | S14: =(($B$4+$G$5)/365)*R14 -> 0.34951579 | T14: =INDEX(DE_Base_Profile!$N$6:$Q$29,ROW()-13,MATCH($B$9,DE_Base_Profile!$N$5:$Q$5,0)) -> 0.125 | U14: =($G$6/365)*T14 -> 0 | V14: =S14+U14 -> 0.34951579 | W14: =IF($G$7=0,0,V14/($G$7/365)) -> 0.036449504 | X14: =W14-N14 -> 0.0063495035
A15: 2月 | B15: =DE_Base_Profile!B7 -> 0.0791 | C15: =$B$4*B15 -> 276.85 | D15: =1+IF(OR($B$6="Air conditioning",$B$6="Heat pump (heating & cooling)"),IF(DE_Base_Profile!D7=1,$G$8-1,0),0)+IF(OR($B$6="Electric heating",$B$6="Heat pump (heating & cooling)"),IF(DE_Base_Profile!E7=1,$G$9-1,0),0) -> 1 | E15: =C15*D15 -> 276.85 | F15: =IF($B$6="Electric heating",IF(DE_Base_Profile!E7=1,B15*$G$9,0),IF($B$6="Heat pump (heating & cooling)",IF(DE_Base_Profile!D7=1,B15*$G$8,0)+IF(DE_Base_Profile!E7=1,B15*$G$9,0),0)) -> 0 | G15: =IF(SUM($F$14:$F$25)=0,0,$G$5*F15/SUM($F$14:$F$25)) -> 0 | H15: =$G$6/12 -> 0 | I15: =E15/SUM($E$14:$E$25)*$B$4+G15+H15 -> 276.85 | J15: =I15/$G$7 -> 0.0791 | K15: =J15-B15 -> 0 | M15: 1 | N15: =DE_Base_Profile!I7 -> 0.0258 | O15: =IF(DE_Base_Profile!J7=1,INDEX(DE_Lookups!$B$2:$B$4,MATCH($B$5,DE_Lookups!$A$2:$A$4,0)),1) -> 1 | P15: =IF(OR($B$6="Air conditioning",$B$6="Heat pump (heating & cooling)"),IF(DE_Base_Profile!K7=1,$G$10,1),1)*IF(OR($B$6="Electric heating",$B$6="Heat pump (heating & cooling)"),IF(DE_Base_Profile!L7=1,$G$11,1),1) -> 1 | Q15: =N15*O15*P15 -> 0.0258 | R15: =Q15/SUM($Q$14:$Q$37) -> 0.031242432 | S15: =(($B$4+$G$5)/365)*R15 -> 0.29958496 | T15: =INDEX(DE_Base_Profile!$N$6:$Q$29,ROW()-13,MATCH($B$9,DE_Base_Profile!$N$5:$Q$5,0)) -> 0.125 | U15: =($G$6/365)*T15 -> 0 | V15: =S15+U15 -> 0.29958496 | W15: =IF($G$7=0,0,V15/($G$7/365)) -> 0.031242432 | X15: =W15-N15 -> 0.0054424316
A16: 3月 | B16: =DE_Base_Profile!B8 -> 0.0773 | C16: =$B$4*B16 -> 270.55 | D16: =1+IF(OR($B$6="Air conditioning",$B$6="Heat pump (heating & cooling)"),IF(DE_Base_Profile!D8=1,$G$8-1,0),0)+IF(OR($B$6="Electric heating",$B$6="Heat pump (heating & cooling)"),IF(DE_Base_Profile!E8=1,$G$9-1,0),0) -> 1 | E16: =C16*D16 -> 270.55 | F16: =IF($B$6="Electric heating",IF(DE_Base_Profile!E8=1,B16*$G$9,0),IF($B$6="Heat pump (heating & cooling)",IF(DE_Base_Profile!D8=1,B16*$G$8,0)+IF(DE_Base_Profile!E8=1,B16*$G$9,0),0)) -> 0 | G16: =IF(SUM($F$14:$F$25)=0,0,$G$5*F16/SUM($F$14:$F$25)) -> 0 | H16: =$G$6/12 -> 0 | I16: =E16/SUM($E$14:$E$25)*$B$4+G16+H16 -> 270.55 | J16: =I16/$G$7 -> 0.0773 | K16: =J16-B16 -> 0 | M16: 2 | N16: =DE_Base_Profile!I8 -> 0.0239 | O16: =IF(DE_Base_Profile!J8=1,INDEX(DE_Lookups!$B$2:$B$4,MATCH($B$5,DE_Lookups!$A$2:$A$4,0)),1) -> 1 | P16: =IF(OR($B$6="Air conditioning",$B$6="Heat pump (heating & cooling)"),IF(DE_Base_Profile!K8=1,$G$10,1),1)*IF(OR($B$6="Electric heating",$B$6="Heat pump (heating & cooling)"),IF(DE_Base_Profile!L8=1,$G$11,1),1) -> 1 | Q16: =N16*O16*P16 -> 0.0239 | R16: =Q16/SUM($Q$14:$Q$37) -> 0.028941632 | S16: =(($B$4+$G$5)/365)*R16 -> 0.2775225 | T16: =INDEX(DE_Base_Profile!$N$6:$Q$29,ROW()-13,MATCH($B$9,DE_Base_Profile!$N$5:$Q$5,0)) -> 0.125 | U16: =($G$6/365)*T16 -> 0 | V16: =S16+U16 -> 0.2775225 | W16: =IF($G$7=0,0,V16/($G$7/365)) -> 0.028941632 | X16: =W16-N16 -> 0.0050416324
A17: 4月 | B17: =DE_Base_Profile!B9 -> 0.0822 | C17: =$B$4*B17 -> 287.7 | D17: =1+IF(OR($B$6="Air conditioning",$B$6="Heat pump (heating & cooling)"),IF(DE_Base_Profile!D9=1,$G$8-1,0),0)+IF(OR($B$6="Electric heating",$B$6="Heat pump (heating & cooling)"),IF(DE_Base_Profile!E9=1,$G$9-1,0),0) -> 1 | E17: =C17*D17 -> 287.7 | F17: =IF($B$6="Electric heating",IF(DE_Base_Profile!E9=1,B17*$G$9,0),IF($B$6="Heat pump (heating & cooling)",IF(DE_Base_Profile!D9=1,B17*$G$8,0)+IF(DE_Base_Profile!E9=1,B17*$G$9,0),0)) -> 0 | G17: =IF(SUM($F$14:$F$25)=0,0,$G$5*F17/SUM($F$14:$F$25)) -> 0 | H17: =$G$6/12 -> 0 | I17: =E17/SUM($E$14:$E$25)*$B$4+G17+H17 -> 287.7 | J17: =I17/$G$7 -> 0.0822 | K17: =J17-B17 -> 0 | M17: 3 | N17: =DE_Base_Profile!I9 -> 0.0232 | O17: =IF(DE_Base_Profile!J9=1,INDEX(DE_Lookups!$B$2:$B$4,MATCH($B$5,DE_Lookups!$A$2:$A$4,0)),1) -> 1 | P17: =IF(OR($B$6="Air conditioning",$B$6="Heat pump (heating & cooling)"),IF(DE_Base_Profile!K9=1,$G$10,1),1)*IF(OR($B$6="Electric heating",$B$6="Heat pump (heating & cooling)"),IF(DE_Base_Profile!L9=1,$G$11,1),1) -> 1 | Q17: =N17*O17*P17 -> 0.0232 | R17: =Q17/SUM($Q$14:$Q$37) -> 0.028093969 | S17: =(($B$4+$G$5)/365)*R17 -> 0.26939423 | T17: =INDEX(DE_Base_Profile!$N$6:$Q$29,ROW()-13,MATCH($B$9,DE_Base_Profile!$N$5:$Q$5,0)) -> 0.125 | U17: =($G$6/365)*T17 -> 0 | V17: =S17+U17 -> 0.26939423 | W17: =IF($G$7=0,0,V17/($G$7/365)) -> 0.028093969 | X17: =W17-N17 -> 0.0048939695
A18: 5月 | B18: =DE_Base_Profile!B10 -> 0.0839 | C18: =$B$4*B18 -> 293.65 | D18: =1+IF(OR($B$6="Air conditioning",$B$6="Heat pump (heating & cooling)"),IF(DE_Base_Profile!D10=1,$G$8-1,0),0)+IF(OR($B$6="Electric heating",$B$6="Heat pump (heating & cooling)"),IF(DE_Base_Profile!E10=1,$G$9-1,0),0) -> 1 | E18: =C18*D18 -> 293.65 | F18: =IF($B$6="Electric heating",IF(DE_Base_Profile!E10=1,B18*$G$9,0),IF($B$6="Heat pump (heating & cooling)",IF(DE_Base_Profile!D10=1,B18*$G$8,0)+IF(DE_Base_Profile!E10=1,B18*$G$9,0),0)) -> 0 | G18: =IF(SUM($F$14:$F$25)=0,0,$G$5*F18/SUM($F$14:$F$25)) -> 0 | H18: =$G$6/12 -> 0 | I18: =E18/SUM($E$14:$E$25)*$B$4+G18+H18 -> 293.65 | J18: =I18/$G$7 -> 0.0839 | K18: =J18-B18 -> 0 | M18: 4 | N18: =DE_Base_Profile!I10 -> 0.0236 | O18: =IF(DE_Base_Profile!J10=1,INDEX(DE_Lookups!$B$2:$B$4,MATCH($B$5,DE_Lookups!$A$2:$A$4,0)),1) -> 1 | P18: =IF(OR($B$6="Air conditioning",$B$6="Heat pump (heating & cooling)"),IF(DE_Base_Profile!K10=1,$G$10,1),1)*IF(OR($B$6="Electric heating",$B$6="Heat pump (heating & cooling)"),IF(DE_Base_Profile!L10=1,$G$11,1),1) -> 1 | Q18: =N18*O18*P18 -> 0.0236 | R18: =Q18/SUM($Q$14:$Q$37) -> 0.028578348 | S18: =(($B$4+$G$5)/365)*R18 -> 0.27403896 | T18: =INDEX(DE_Base_Profile!$N$6:$Q$29,ROW()-13,MATCH($B$9,DE_Base_Profile!$N$5:$Q$5,0)) -> 0.125 | U18: =($G$6/365)*T18 -> 0 | V18: =S18+U18 -> 0.27403896 | W18: =IF($G$7=0,0,V18/($G$7/365)) -> 0.028578348 | X18: =W18-N18 -> 0.0049783483
A19: 6月 | B19: =DE_Base_Profile!B11 -> 0.0876 | C19: =$B$4*B19 -> 306.6 | D19: =1+IF(OR($B$6="Air conditioning",$B$6="Heat pump (heating & cooling)"),IF(DE_Base_Profile!D11=1,$G$8-1,0),0)+IF(OR($B$6="Electric heating",$B$6="Heat pump (heating & cooling)"),IF(DE_Base_Profile!E11=1,$G$9-1,0),0) -> 1 | E19: =C19*D19 -> 306.6 | F19: =IF($B$6="Electric heating",IF(DE_Base_Profile!E11=1,B19*$G$9,0),IF($B$6="Heat pump (heating & cooling)",IF(DE_Base_Profile!D11=1,B19*$G$8,0)+IF(DE_Base_Profile!E11=1,B19*$G$9,0),0)) -> 0 | G19: =IF(SUM($F$14:$F$25)=0,0,$G$5*F19/SUM($F$14:$F$25)) -> 0 | H19: =$G$6/12 -> 0 | I19: =E19/SUM($E$14:$E$25)*$B$4+G19+H19 -> 306.6 | J19: =I19/$G$7 -> 0.0876 | K19: =J19-B19 -> 0 | M19: 5 | N19: =DE_Base_Profile!I11 -> 0.0252 | O19: =IF(DE_Base_Profile!J11=1,INDEX(DE_Lookups!$B$2:$B$4,MATCH($B$5,DE_Lookups!$A$2:$A$4,0)),1) -> 1 | P19: =IF(OR($B$6="Air conditioning",$B$6="Heat pump (heating & cooling)"),IF(DE_Base_Profile!K11=1,$G$10,1),1)*IF(OR($B$6="Electric heating",$B$6="Heat pump (heating & cooling)"),IF(DE_Base_Profile!L11=1,$G$11,1),1) -> 1 | Q19: =N19*O19*P19 -> 0.0252 | R19: =Q19/SUM($Q$14:$Q$37) -> 0.030515863 | S19: =(($B$4+$G$5)/365)*R19 -> 0.29261787 | T19: =INDEX(DE_Base_Profile!$N$6:$Q$29,ROW()-13,MATCH($B$9,DE_Base_Profile!$N$5:$Q$5,0)) -> 0.125 | U19: =($G$6/365)*T19 -> 0 | V19: =S19+U19 -> 0.29261787 | W19: =IF($G$7=0,0,V19/($G$7/365)) -> 0.030515863 | X19: =W19-N19 -> 0.0053158634
A20: 7月 | B20: =DE_Base_Profile!B12 -> 0.0917 | C20: =$B$4*B20 -> 320.95 | D20: =1+IF(OR($B$6="Air conditioning",$B$6="Heat pump (heating & cooling)"),IF(DE_Base_Profile!D12=1,$G$8-1,0),0)+IF(OR($B$6="Electric heating",$B$6="Heat pump (heating & cooling)"),IF(DE_Base_Profile!E12=1,$G$9-1,0),0) -> 1 | E20: =C20*D20 -> 320.95 | F20: =IF($B$6="Electric heating",IF(DE_Base_Profile!E12=1,B20*$G$9,0),IF($B$6="Heat pump (heating & cooling)",IF(DE_Base_Profile!D12=1,B20*$G$8,0)+IF(DE_Base_Profile!E12=1,B20*$G$9,0),0)) -> 0 | G20: =IF(SUM($F$14:$F$25)=0,0,$G$5*F20/SUM($F$14:$F$25)) -> 0 | H20: =$G$6/12 -> 0 | I20: =E20/SUM($E$14:$E$25)*$B$4+G20+H20 -> 320.95 | J20: =I20/$G$7 -> 0.0917 | K20: =J20-B20 -> 0 | M20: 6 | N20: =DE_Base_Profile!I12 -> 0.03 | O20: =IF(DE_Base_Profile!J12=1,INDEX(DE_Lookups!$B$2:$B$4,MATCH($B$5,DE_Lookups!$A$2:$A$4,0)),1) -> 1 | P20: =IF(OR($B$6="Air conditioning",$B$6="Heat pump (heating & cooling)"),IF(DE_Base_Profile!K12=1,$G$10,1),1)*IF(OR($B$6="Electric heating",$B$6="Heat pump (heating & cooling)"),IF(DE_Base_Profile!L12=1,$G$11,1),1) -> 1 | Q20: =N20*O20*P20 -> 0.03 | R20: =Q20/SUM($Q$14:$Q$37) -> 0.036328409 | S20: =(($B$4+$G$5)/365)*R20 -> 0.34835461 | T20: =INDEX(DE_Base_Profile!$N$6:$Q$29,ROW()-13,MATCH($B$9,DE_Base_Profile!$N$5:$Q$5,0)) -> 0 | U20: =($G$6/365)*T20 -> 0 | V20: =S20+U20 -> 0.34835461 | W20: =IF($G$7=0,0,V20/($G$7/365)) -> 0.036328409 | X20: =W20-N20 -> 0.0063284088
A21: 8月 | B21: =DE_Base_Profile!B13 -> 0.0887 | C21: =$B$4*B21 -> 310.45 | D21: =1+IF(OR($B$6="Air conditioning",$B$6="Heat pump (heating & cooling)"),IF(DE_Base_Profile!D13=1,$G$8-1,0),0)+IF(OR($B$6="Electric heating",$B$6="Heat pump (heating & cooling)"),IF(DE_Base_Profile!E13=1,$G$9-1,0),0) -> 1 | E21: =C21*D21 -> 310.45 | F21: =IF($B$6="Electric heating",IF(DE_Base_Profile!E13=1,B21*$G$9,0),IF($B$6="Heat pump (heating & cooling)",IF(DE_Base_Profile!D13=1,B21*$G$8,0)+IF(DE_Base_Profile!E13=1,B21*$G$9,0),0)) -> 0 | G21: =IF(SUM($F$14:$F$25)=0,0,$G$5*F21/SUM($F$14:$F$25)) -> 0 | H21: =$G$6/12 -> 0 | I21: =E21/SUM($E$14:$E$25)*$B$4+G21+H21 -> 310.45 | J21: =I21/$G$7 -> 0.0887 | K21: =J21-B21 -> 0 | M21: 7 | N21: =DE_Base_Profile!I13 -> 0.0358 | O21: =IF(DE_Base_Profile!J13=1,INDEX(DE_Lookups!$B$2:$B$4,MATCH($B$5,DE_Lookups!$A$2:$A$4,0)),1) -> 1 | P21: =IF(OR($B$6="Air conditioning",$B$6="Heat pump (heating & cooling)"),IF(DE_Base_Profile!K13=1,$G$10,1),1)*IF(OR($B$6="Electric heating",$B$6="Heat pump (heating & cooling)"),IF(DE_Base_Profile!L13=1,$G$11,1),1) -> 1 | Q21: =N21*O21*P21 -> 0.0358 | R21: =Q21/SUM($Q$14:$Q$37) -> 0.043351901 | S21: =(($B$4+$G$5)/365)*R21 -> 0.41570316 | T21: =INDEX(DE_Base_Profile!$N$6:$Q$29,ROW()-13,MATCH($B$9,DE_Base_Profile!$N$5:$Q$5,0)) -> 0 | U21: =($G$6/365)*T21 -> 0 | V21: =S21+U21 -> 0.41570316 | W21: =IF($G$7=0,0,V21/($G$7/365)) -> 0.043351901 | X21: =W21-N21 -> 0.0075519012
A22: 9月 | B22: =DE_Base_Profile!B14 -> 0.0853 | C22: =$B$4*B22 -> 298.55 | D22: =1+IF(OR($B$6="Air conditioning",$B$6="Heat pump (heating & cooling)"),IF(DE_Base_Profile!D14=1,$G$8-1,0),0)+IF(OR($B$6="Electric heating",$B$6="Heat pump (heating & cooling)"),IF(DE_Base_Profile!E14=1,$G$9-1,0),0) -> 1 | E22: =C22*D22 -> 298.55 | F22: =IF($B$6="Electric heating",IF(DE_Base_Profile!E14=1,B22*$G$9,0),IF($B$6="Heat pump (heating & cooling)",IF(DE_Base_Profile!D14=1,B22*$G$8,0)+IF(DE_Base_Profile!E14=1,B22*$G$9,0),0)) -> 0 | G22: =IF(SUM($F$14:$F$25)=0,0,$G$5*F22/SUM($F$14:$F$25)) -> 0 | H22: =$G$6/12 -> 0 | I22: =E22/SUM($E$14:$E$25)*$B$4+G22+H22 -> 298.55 | J22: =I22/$G$7 -> 0.0853 | K22: =J22-B22 -> 0 | M22: 8 | N22: =DE_Base_Profile!I14 -> 0.041 | O22: =IF(DE_Base_Profile!J14=1,INDEX(DE_Lookups!$B$2:$B$4,MATCH($B$5,DE_Lookups!$A$2:$A$4,0)),1) -> 1 | P22: =IF(OR($B$6="Air conditioning",$B$6="Heat pump (heating & cooling)"),IF(DE_Base_Profile!K14=1,$G$10,1),1)*IF(OR($B$6="Electric heating",$B$6="Heat pump (heating & cooling)"),IF(DE_Base_Profile!L14=1,$G$11,1),1) -> 1 | Q22: =N22*O22*P22 -> 0.041 | R22: =Q22/SUM($Q$14:$Q$37) -> 0.049648825 | S22: =(($B$4+$G$5)/365)*R22 -> 0.47608463 | T22: =INDEX(DE_Base_Profile!$N$6:$Q$29,ROW()-13,MATCH($B$9,DE_Base_Profile!$N$5:$Q$5,0)) -> 0 | U22: =($G$6/365)*T22 -> 0 | V22: =S22+U22 -> 0.47608463 | W22: =IF($G$7=0,0,V22/($G$7/365)) -> 0.049648825 | X22: =W22-N22 -> 0.0086488254
A23: 10月 | B23: =DE_Base_Profile!B15 -> 0.0838 | C23: =$B$4*B23 -> 293.3 | D23: =1+IF(OR($B$6="Air conditioning",$B$6="Heat pump (heating & cooling)"),IF(DE_Base_Profile!D15=1,$G$8-1,0),0)+IF(OR($B$6="Electric heating",$B$6="Heat pump (heating & cooling)"),IF(DE_Base_Profile!E15=1,$G$9-1,0),0) -> 1 | E23: =C23*D23 -> 293.3 | F23: =IF($B$6="Electric heating",IF(DE_Base_Profile!E15=1,B23*$G$9,0),IF($B$6="Heat pump (heating & cooling)",IF(DE_Base_Profile!D15=1,B23*$G$8,0)+IF(DE_Base_Profile!E15=1,B23*$G$9,0),0)) -> 0 | G23: =IF(SUM($F$14:$F$25)=0,0,$G$5*F23/SUM($F$14:$F$25)) -> 0 | H23: =$G$6/12 -> 0 | I23: =E23/SUM($E$14:$E$25)*$B$4+G23+H23 -> 293.3 | J23: =I23/$G$7 -> 0.0838 | K23: =J23-B23 -> 0 | M23: 9 | N23: =DE_Base_Profile!I15 -> 0.0446 | O23: =IF(DE_Base_Profile!J15=1,INDEX(DE_Lookups!$B$2:$B$4,MATCH($B$5,DE_Lookups!$A$2:$A$4,0)),1) -> 0.6 | P23: =IF(OR($B$6="Air conditioning",$B$6="Heat pump (heating & cooling)"),IF(DE_Base_Profile!K15=1,$G$10,1),1)*IF(OR($B$6="Electric heating",$B$6="Heat pump (heating & cooling)"),IF(DE_Base_Profile!L15=1,$G$11,1),1) -> 1 | Q23: =N23*O23*P23 -> 0.02676 | R23: =Q23/SUM($Q$14:$Q$37) -> 0.032404941 | S23: =(($B$4+$G$5)/365)*R23 -> 0.31073231 | T23: =INDEX(DE_Base_Profile!$N$6:$Q$29,ROW()-13,MATCH($B$9,DE_Base_Profile!$N$5:$Q$5,0)) -> 0 | U23: =($G$6/365)*T23 -> 0 | V23: =S23+U23 -> 0.31073231 | W23: =IF($G$7=0,0,V23/($G$7/365)) -> 0.032404941 | X23: =W23-N23 -> -0.012195059
A24: 11月 | B24: =DE_Base_Profile!B16 -> 0.0819 | C24: =$B$4*B24 -> 286.65 | D24: =1+IF(OR($B$6="Air conditioning",$B$6="Heat pump (heating & cooling)"),IF(DE_Base_Profile!D16=1,$G$8-1,0),0)+IF(OR($B$6="Electric heating",$B$6="Heat pump (heating & cooling)"),IF(DE_Base_Profile!E16=1,$G$9-1,0),0) -> 1 | E24: =C24*D24 -> 286.65 | F24: =IF($B$6="Electric heating",IF(DE_Base_Profile!E16=1,B24*$G$9,0),IF($B$6="Heat pump (heating & cooling)",IF(DE_Base_Profile!D16=1,B24*$G$8,0)+IF(DE_Base_Profile!E16=1,B24*$G$9,0),0)) -> 0 | G24: =IF(SUM($F$14:$F$25)=0,0,$G$5*F24/SUM($F$14:$F$25)) -> 0 | H24: =$G$6/12 -> 0 | I24: =E24/SUM($E$14:$E$25)*$B$4+G24+H24 -> 286.65 | J24: =I24/$G$7 -> 0.0819 | K24: =J24-B24 -> 0 | M24: 10 | N24: =DE_Base_Profile!I16 -> 0.0474 | O24: =IF(DE_Base_Profile!J16=1,INDEX(DE_Lookups!$B$2:$B$4,MATCH($B$5,DE_Lookups!$A$2:$A$4,0)),1) -> 0.6 | P24: =IF(OR($B$6="Air conditioning",$B$6="Heat pump (heating & cooling)"),IF(DE_Base_Profile!K16=1,$G$10,1),1)*IF(OR($B$6="Electric heating",$B$6="Heat pump (heating & cooling)"),IF(DE_Base_Profile!L16=1,$G$11,1),1) -> 1 | Q24: =N24*O24*P24 -> 0.02844 | R24: =Q24/SUM($Q$14:$Q$37) -> 0.034439332 | S24: =(($B$4+$G$5)/365)*R24 -> 0.33024017 | T24: =INDEX(DE_Base_Profile!$N$6:$Q$29,ROW()-13,MATCH($B$9,DE_Base_Profile!$N$5:$Q$5,0)) -> 0 | U24: =($G$6/365)*T24 -> 0 | V24: =S24+U24 -> 0.33024017 | W24: =IF($G$7=0,0,V24/($G$7/365)) -> 0.034439332 | X24: =W24-N24 -> -0.012960668
A25: 12月 | B25: =DE_Base_Profile!B17 -> 0.0796 | C25: =$B$4*B25 -> 278.6 | D25: =1+IF(OR($B$6="Air conditioning",$B$6="Heat pump (heating & cooling)"),IF(DE_Base_Profile!D17=1,$G$8-1,0),0)+IF(OR($B$6="Electric heating",$B$6="Heat pump (heating & cooling)"),IF(DE_Base_Profile!E17=1,$G$9-1,0),0) -> 1 | E25: =C25*D25 -> 278.6 | F25: =IF($B$6="Electric heating",IF(DE_Base_Profile!E17=1,B25*$G$9,0),IF($B$6="Heat pump (heating & cooling)",IF(DE_Base_Profile!D17=1,B25*$G$8,0)+IF(DE_Base_Profile!E17=1,B25*$G$9,0),0)) -> 0 | G25: =IF(SUM($F$14:$F$25)=0,0,$G$5*F25/SUM($F$14:$F$25)) -> 0 | H25: =$G$6/12 -> 0 | I25: =E25/SUM($E$14:$E$25)*$B$4+G25+H25 -> 278.6 | J25: =I25/$G$7 -> 0.0796 | K25: =J25-B25 -> 0 | M25: 11 | N25: =DE_Base_Profile!I17 -> 0.0518 | O25: =IF(DE_Base_Profile!J17=1,INDEX(DE_Lookups!$B$2:$B$4,MATCH($B$5,DE_Lookups!$A$2:$A$4,0)),1) -> 0.6 | P25: =IF(OR($B$6="Air conditioning",$B$6="Heat pump (heating & cooling)"),IF(DE_Base_Profile!K17=1,$G$10,1),1)*IF(OR($B$6="Electric heating",$B$6="Heat pump (heating & cooling)"),IF(DE_Base_Profile!L17=1,$G$11,1),1) -> 1 | Q25: =N25*O25*P25 -> 0.03108 | R25: =Q25/SUM($Q$14:$Q$37) -> 0.037636232 | S25: =(($B$4+$G$5)/365)*R25 -> 0.36089537 | T25: =INDEX(DE_Base_Profile!$N$6:$Q$29,ROW()-13,MATCH($B$9,DE_Base_Profile!$N$5:$Q$5,0)) -> 0 | U25: =($G$6/365)*T25 -> 0 | V25: =S25+U25 -> 0.36089537 | W25: =IF($G$7=0,0,V25/($G$7/365)) -> 0.037636232 | X25: =W25-N25 -> -0.014163768
A26: Total | B26: =SUM(B14:B25) -> 1 | C26: =SUM(C14:C25) -> 3500 | E26: =SUM(E14:E25) -> 3500 | F26: =SUM(F14:F25) -> 0 | G26: =SUM(G14:G25) -> 0 | H26: =SUM(H14:H25) -> 0 | I26: =SUM(I14:I25) -> 3500 | J26: =SUM(J14:J25) -> 1 | K26: =SUM(K14:K25) -> 0 | M26: 12 | N26: =DE_Base_Profile!I18 -> 0.0513 | O26: =IF(DE_Base_Profile!J18=1,INDEX(DE_Lookups!$B$2:$B$4,MATCH($B$5,DE_Lookups!$A$2:$A$4,0)),1) -> 0.6 | P26: =IF(OR($B$6="Air conditioning",$B$6="Heat pump (heating & cooling)"),IF(DE_Base_Profile!K18=1,$G$10,1),1)*IF(OR($B$6="Electric heating",$B$6="Heat pump (heating & cooling)"),IF(DE_Base_Profile!L18=1,$G$11,1),1) -> 1 | Q26: =N26*O26*P26 -> 0.03078 | R26: =Q26/SUM($Q$14:$Q$37) -> 0.037272947 | S26: =(($B$4+$G$5)/365)*R26 -> 0.35741182 | T26: =INDEX(DE_Base_Profile!$N$6:$Q$29,ROW()-13,MATCH($B$9,DE_Base_Profile!$N$5:$Q$5,0)) -> 0 | U26: =($G$6/365)*T26 -> 0 | V26: =S26+U26 -> 0.35741182 | W26: =IF($G$7=0,0,V26/($G$7/365)) -> 0.037272947 | X26: =W26-N26 -> -0.014027053
M27: 13 | N27: =DE_Base_Profile!I19 -> 0.0481 | O27: =IF(DE_Base_Profile!J19=1,INDEX(DE_Lookups!$B$2:$B$4,MATCH($B$5,DE_Lookups!$A$2:$A$4,0)),1) -> 0.6 | P27: =IF(OR($B$6="Air conditioning",$B$6="Heat pump (heating & cooling)"),IF(DE_Base_Profile!K19=1,$G$10,1),1)*IF(OR($B$6="Electric heating",$B$6="Heat pump (heating & cooling)"),IF(DE_Base_Profile!L19=1,$G$11,1),1) -> 1 | Q27: =N27*O27*P27 -> 0.02886 | R27: =Q27/SUM($Q$14:$Q$37) -> 0.034947929 | S27: =(($B$4+$G$5)/365)*R27 -> 0.33511713 | T27: =INDEX(DE_Base_Profile!$N$6:$Q$29,ROW()-13,MATCH($B$9,DE_Base_Profile!$N$5:$Q$5,0)) -> 0 | U27: =($G$6/365)*T27 -> 0 | V27: =S27+U27 -> 0.33511713 | W27: =IF($G$7=0,0,V27/($G$7/365)) -> 0.034947929 | X27: =W27-N27 -> -0.013152071
M28: 14 | N28: =DE_Base_Profile!I20 -> 0.0459 | O28: =IF(DE_Base_Profile!J20=1,INDEX(DE_Lookups!$B$2:$B$4,MATCH($B$5,DE_Lookups!$A$2:$A$4,0)),1) -> 0.6 | P28: =IF(OR($B$6="Air conditioning",$B$6="Heat pump (heating & cooling)"),IF(DE_Base_Profile!K20=1,$G$10,1),1)*IF(OR($B$6="Electric heating",$B$6="Heat pump (heating & cooling)"),IF(DE_Base_Profile!L20=1,$G$11,1),1) -> 1 | Q28: =N28*O28*P28 -> 0.02754 | R28: =Q28/SUM($Q$14:$Q$37) -> 0.033349479 | S28: =(($B$4+$G$5)/365)*R28 -> 0.31978953 | T28: =INDEX(DE_Base_Profile!$N$6:$Q$29,ROW()-13,MATCH($B$9,DE_Base_Profile!$N$5:$Q$5,0)) -> 0 | U28: =($G$6/365)*T28 -> 0 | V28: =S28+U28 -> 0.31978953 | W28: =IF($G$7=0,0,V28/($G$7/365)) -> 0.033349479 | X28: =W28-N28 -> -0.012550521
M29: 15 | N29: =DE_Base_Profile!I21 -> 0.0454 | O29: =IF(DE_Base_Profile!J21=1,INDEX(DE_Lookups!$B$2:$B$4,MATCH($B$5,DE_Lookups!$A$2:$A$4,0)),1) -> 0.6 | P29: =IF(OR($B$6="Air conditioning",$B$6="Heat pump (heating & cooling)"),IF(DE_Base_Profile!K21=1,$G$10,1),1)*IF(OR($B$6="Electric heating",$B$6="Heat pump (heating & cooling)"),IF(DE_Base_Profile!L21=1,$G$11,1),1) -> 1 | Q29: =N29*O29*P29 -> 0.02724 | R29: =Q29/SUM($Q$14:$Q$37) -> 0.032986195 | S29: =(($B$4+$G$5)/365)*R29 -> 0.31630598 | T29: =INDEX(DE_Base_Profile!$N$6:$Q$29,ROW()-13,MATCH($B$9,DE_Base_Profile!$N$5:$Q$5,0)) -> 0 | U29: =($G$6/365)*T29 -> 0 | V29: =S29+U29 -> 0.31630598 | W29: =IF($G$7=0,0,V29/($G$7/365)) -> 0.032986195 | X29: =W29-N29 -> -0.012413805
M30: 16 | N30: =DE_Base_Profile!I22 -> 0.0475 | O30: =IF(DE_Base_Profile!J22=1,INDEX(DE_Lookups!$B$2:$B$4,MATCH($B$5,DE_Lookups!$A$2:$A$4,0)),1) -> 0.6 | P30: =IF(OR($B$6="Air conditioning",$B$6="Heat pump (heating & cooling)"),IF(DE_Base_Profile!K22=1,$G$10,1),1)*IF(OR($B$6="Electric heating",$B$6="Heat pump (heating & cooling)"),IF(DE_Base_Profile!L22=1,$G$11,1),1) -> 1 | Q30: =N30*O30*P30 -> 0.0285 | R30: =Q30/SUM($Q$14:$Q$37) -> 0.034511988 | S30: =(($B$4+$G$5)/365)*R30 -> 0.33093687 | T30: =INDEX(DE_Base_Profile!$N$6:$Q$29,ROW()-13,MATCH($B$9,DE_Base_Profile!$N$5:$Q$5,0)) -> 0 | U30: =($G$6/365)*T30 -> 0 | V30: =S30+U30 -> 0.33093687 | W30: =IF($G$7=0,0,V30/($G$7/365)) -> 0.034511988 | X30: =W30-N30 -> -0.012988012
M31: 17 | N31: =DE_Base_Profile!I23 -> 0.0535 | O31: =IF(DE_Base_Profile!J23=1,INDEX(DE_Lookups!$B$2:$B$4,MATCH($B$5,DE_Lookups!$A$2:$A$4,0)),1) -> 0.6 | P31: =IF(OR($B$6="Air conditioning",$B$6="Heat pump (heating & cooling)"),IF(DE_Base_Profile!K23=1,$G$10,1),1)*IF(OR($B$6="Electric heating",$B$6="Heat pump (heating & cooling)"),IF(DE_Base_Profile!L23=1,$G$11,1),1) -> 1 | Q31: =N31*O31*P31 -> 0.0321 | R31: =Q31/SUM($Q$14:$Q$37) -> 0.038871397 | S31: =(($B$4+$G$5)/365)*R31 -> 0.37273943 | T31: =INDEX(DE_Base_Profile!$N$6:$Q$29,ROW()-13,MATCH($B$9,DE_Base_Profile!$N$5:$Q$5,0)) -> 0 | U31: =($G$6/365)*T31 -> 0 | V31: =S31+U31 -> 0.37273943 | W31: =IF($G$7=0,0,V31/($G$7/365)) -> 0.038871397 | X31: =W31-N31 -> -0.014628603
M32: 18 | N32: =DE_Base_Profile!I24 -> 0.0587 | O32: =IF(DE_Base_Profile!J24=1,INDEX(DE_Lookups!$B$2:$B$4,MATCH($B$5,DE_Lookups!$A$2:$A$4,0)),1) -> 1 | P32: =IF(OR($B$6="Air conditioning",$B$6="Heat pump (heating & cooling)"),IF(DE_Base_Profile!K24=1,$G$10,1),1)*IF(OR($B$6="Electric heating",$B$6="Heat pump (heating & cooling)"),IF(DE_Base_Profile!L24=1,$G$11,1),1) -> 1 | Q32: =N32*O32*P32 -> 0.0587 | R32: =Q32/SUM($Q$14:$Q$37) -> 0.071082587 | S32: =(($B$4+$G$5)/365)*R32 -> 0.68161384 | T32: =INDEX(DE_Base_Profile!$N$6:$Q$29,ROW()-13,MATCH($B$9,DE_Base_Profile!$N$5:$Q$5,0)) -> 0 | U32: =($G$6/365)*T32 -> 0 | V32: =S32+U32 -> 0.68161384 | W32: =IF($G$7=0,0,V32/($G$7/365)) -> 0.071082587 | X32: =W32-N32 -> 0.012382587
M33: 19 | N33: =DE_Base_Profile!I25 -> 0.0591 | O33: =IF(DE_Base_Profile!J25=1,INDEX(DE_Lookups!$B$2:$B$4,MATCH($B$5,DE_Lookups!$A$2:$A$4,0)),1) -> 1 | P33: =IF(OR($B$6="Air conditioning",$B$6="Heat pump (heating & cooling)"),IF(DE_Base_Profile!K25=1,$G$10,1),1)*IF(OR($B$6="Electric heating",$B$6="Heat pump (heating & cooling)"),IF(DE_Base_Profile!L25=1,$G$11,1),1) -> 1 | Q33: =N33*O33*P33 -> 0.0591 | R33: =Q33/SUM($Q$14:$Q$37) -> 0.071566965 | S33: =(($B$4+$G$5)/365)*R33 -> 0.68625857 | T33: =INDEX(DE_Base_Profile!$N$6:$Q$29,ROW()-13,MATCH($B$9,DE_Base_Profile!$N$5:$Q$5,0)) -> 0 | U33: =($G$6/365)*T33 -> 0 | V33: =S33+U33 -> 0.68625857 | W33: =IF($G$7=0,0,V33/($G$7/365)) -> 0.071566965 | X33: =W33-N33 -> 0.012466965
M34: 20 | N34: =DE_Base_Profile!I26 -> 0.0556 | O34: =IF(DE_Base_Profile!J26=1,INDEX(DE_Lookups!$B$2:$B$4,MATCH($B$5,DE_Lookups!$A$2:$A$4,0)),1) -> 1 | P34: =IF(OR($B$6="Air conditioning",$B$6="Heat pump (heating & cooling)"),IF(DE_Base_Profile!K26=1,$G$10,1),1)*IF(OR($B$6="Electric heating",$B$6="Heat pump (heating & cooling)"),IF(DE_Base_Profile!L26=1,$G$11,1),1) -> 1 | Q34: =N34*O34*P34 -> 0.0556 | R34: =Q34/SUM($Q$14:$Q$37) -> 0.067328651 | S34: =(($B$4+$G$5)/365)*R34 -> 0.6456172 | T34: =INDEX(DE_Base_Profile!$N$6:$Q$29,ROW()-13,MATCH($B$9,DE_Base_Profile!$N$5:$Q$5,0)) -> 0 | U34: =($G$6/365)*T34 -> 0 | V34: =S34+U34 -> 0.6456172 | W34: =IF($G$7=0,0,V34/($G$7/365)) -> 0.067328651 | X34: =W34-N34 -> 0.011728651
M35: 21 | N35: =DE_Base_Profile!I27 -> 0.0508 | O35: =IF(DE_Base_Profile!J27=1,INDEX(DE_Lookups!$B$2:$B$4,MATCH($B$5,DE_Lookups!$A$2:$A$4,0)),1) -> 1 | P35: =IF(OR($B$6="Air conditioning",$B$6="Heat pump (heating & cooling)"),IF(DE_Base_Profile!K27=1,$G$10,1),1)*IF(OR($B$6="Electric heating",$B$6="Heat pump (heating & cooling)"),IF(DE_Base_Profile!L27=1,$G$11,1),1) -> 1 | Q35: =N35*O35*P35 -> 0.0508 | R35: =Q35/SUM($Q$14:$Q$37) -> 0.061516106 | S35: =(($B$4+$G$5)/365)*R35 -> 0.58988046 | T35: =INDEX(DE_Base_Profile!$N$6:$Q$29,ROW()-13,MATCH($B$9,DE_Base_Profile!$N$5:$Q$5,0)) -> 0 | U35: =($G$6/365)*T35 -> 0 | V35: =S35+U35 -> 0.58988046 | W35: =IF($G$7=0,0,V35/($G$7/365)) -> 0.061516106 | X35: =W35-N35 -> 0.010716106
M36: 22 | N36: =DE_Base_Profile!I28 -> 0.0451 | O36: =IF(DE_Base_Profile!J28=1,INDEX(DE_Lookups!$B$2:$B$4,MATCH($B$5,DE_Lookups!$A$2:$A$4,0)),1) -> 1 | P36: =IF(OR($B$6="Air conditioning",$B$6="Heat pump (heating & cooling)"),IF(DE_Base_Profile!K28=1,$G$10,1),1)*IF(OR($B$6="Electric heating",$B$6="Heat pump (heating & cooling)"),IF(DE_Base_Profile!L28=1,$G$11,1),1) -> 1 | Q36: =N36*O36*P36 -> 0.0451 | R36: =Q36/SUM($Q$14:$Q$37) -> 0.054613708 | S36: =(($B$4+$G$5)/365)*R36 -> 0.52369309 | T36: =INDEX(DE_Base_Profile!$N$6:$Q$29,ROW()-13,MATCH($B$9,DE_Base_Profile!$N$5:$Q$5,0)) -> 0.125 | U36: =($G$6/365)*T36 -> 0 | V36: =S36+U36 -> 0.52369309 | W36: =IF($G$7=0,0,V36/($G$7/365)) -> 0.054613708 | X36: =W36-N36 -> 0.0095137079
M37: 23 | N37: =DE_Base_Profile!I29 -> 0.0366 | O37: =IF(DE_Base_Profile!J29=1,INDEX(DE_Lookups!$B$2:$B$4,MATCH($B$5,DE_Lookups!$A$2:$A$4,0)),1) -> 1 | P37: =IF(OR($B$6="Air conditioning",$B$6="Heat pump (heating & cooling)"),IF(DE_Base_Profile!K29=1,$G$10,1),1)*IF(OR($B$6="Electric heating",$B$6="Heat pump (heating & cooling)"),IF(DE_Base_Profile!L29=1,$G$11,1),1) -> 1 | Q37: =N37*O37*P37 -> 0.0366 | R37: =Q37/SUM($Q$14:$Q$37) -> 0.044320659 | S37: =(($B$4+$G$5)/365)*R37 -> 0.42499262 | T37: =INDEX(DE_Base_Profile!$N$6:$Q$29,ROW()-13,MATCH($B$9,DE_Base_Profile!$N$5:$Q$5,0)) -> 0.125 | U37: =($G$6/365)*T37 -> 0 | V37: =S37+U37 -> 0.42499262 | W37: =IF($G$7=0,0,V37/($G$7/365)) -> 0.044320659 | X37: =W37-N37 -> 0.0077206588
M38: Total | N38: =SUM(N14:N37) -> 1 | Q38: =SUM(Q14:Q37) -> 0.8258 | R38: =SUM(R14:R37) -> 1 | S38: =SUM(S14:S37) -> 9.5890411 | T38: =SUM(T14:T37) -> 1 | U38: =SUM(U14:U37) -> 0 | V38: =SUM(V14:V37) -> 9.5890411 | W38: =SUM(W14:W37) -> 1 | X38: =SUM(X14:X37) -> -6.9388939e-18
A40: Interpretation / 解读
A41: Monthly table shows how the annual load is distributed across 12 months after the selected load profile is applied.
A42: 24h table shows an average-day shape. It is not a dispatch model and does not expand to 8,760 hours.

Sheet DE_Option_Monthly
A1: Base annual kWh for comparison scenarios | B1: 3500
A2: Rows compare individual option values on top of the Germany base profile. Monthly outputs show final share and final kWh after simplification logic.
A3: Group | B3: Scenario | C3: Occupancy | D3: System | E3: Usage | F3: EV mileage | G3: EV charging | H3: Annual kWh | I3: 1月 share | J3: 2月 share | K3: 3月 share | L3: 4月 share | M3: 5月 share | N3: 6月 share | O3: 7月 share | P3: 8月 share | Q3: 9月 share | R3: 10月 share | S3: 11月 share | T3: 12月 share | U3: 1月 kWh | V3: 2月 kWh | W3: 3月 kWh | X3: 4月 kWh | Y3: 5月 kWh | Z3: 6月 kWh | AA3: 7月 kWh | AB3: 8月 kWh | AC3: 9月 kWh | AD3: 10月 kWh | AE3: 11月 kWh | AF3: 12月 kWh | AG3: Assumption / 注释
A4: Occupancy | B4: Mostly away during the day | C4: Mostly away during the day | D4: No heating or cooling system | E4: Medium | F4: No electric vehicle | G4: Mostly overnight | H4: =DE_Calc_Compare!H2 -> 3500 | I4: =DE_Calc_Compare!J4 -> 0.0789 | J4: =DE_Calc_Compare!J5 -> 0.0791 | K4: =DE_Calc_Compare!J6 -> 0.0773 | L4: =DE_Calc_Compare!J7 -> 0.0822 | M4: =DE_Calc_Compare!J8 -> 0.0839 | N4: =DE_Calc_Compare!J9 -> 0.0876 | O4: =DE_Calc_Compare!J10 -> 0.0917 | P4: =DE_Calc_Compare!J11 -> 0.0887 | Q4: =DE_Calc_Compare!J12 -> 0.0853 | R4: =DE_Calc_Compare!J13 -> 0.0838 | S4: =DE_Calc_Compare!J14 -> 0.0819 | T4: =DE_Calc_Compare!J15 -> 0.0796 | U4: =DE_Calc_Compare!I4 -> 276.15 | V4: =DE_Calc_Compare!I5 -> 276.85 | W4: =DE_Calc_Compare!I6 -> 270.55 | X4: =DE_Calc_Compare!I7 -> 287.7 | Y4: =DE_Calc_Compare!I8 -> 293.65 | Z4: =DE_Calc_Compare!I9 -> 306.6 | AA4: =DE_Calc_Compare!I10 -> 320.95 | AB4: =DE_Calc_Compare!I11 -> 310.45 | AC4: =DE_Calc_Compare!I12 -> 298.55 | AD4: =DE_Calc_Compare!I13 -> 293.3 | AE4: =DE_Calc_Compare!I14 -> 286.65 | AF4: =DE_Calc_Compare!I15 -> 278.6 | AG4: No HVAC / no EV
A5: Occupancy | B5: Working from home | C5: Working from home | D5: No heating or cooling system | E5: Medium | F5: No electric vehicle | G5: Mostly overnight | H5: =DE_Calc_Compare!H47 -> 3500 | I5: =DE_Calc_Compare!J49 -> 0.0789 | J5: =DE_Calc_Compare!J50 -> 0.0791 | K5: =DE_Calc_Compare!J51 -> 0.0773 | L5: =DE_Calc_Compare!J52 -> 0.0822 | M5: =DE_Calc_Compare!J53 -> 0.0839 | N5: =DE_Calc_Compare!J54 -> 0.0876 | O5: =DE_Calc_Compare!J55 -> 0.0917 | P5: =DE_Calc_Compare!J56 -> 0.0887 | Q5: =DE_Calc_Compare!J57 -> 0.0853 | R5: =DE_Calc_Compare!J58 -> 0.0838 | S5: =DE_Calc_Compare!J59 -> 0.0819 | T5: =DE_Calc_Compare!J60 -> 0.0796 | U5: =DE_Calc_Compare!I49 -> 276.15 | V5: =DE_Calc_Compare!I50 -> 276.85 | W5: =DE_Calc_Compare!I51 -> 270.55 | X5: =DE_Calc_Compare!I52 -> 287.7 | Y5: =DE_Calc_Compare!I53 -> 293.65 | Z5: =DE_Calc_Compare!I54 -> 306.6 | AA5: =DE_Calc_Compare!I55 -> 320.95 | AB5: =DE_Calc_Compare!I56 -> 310.45 | AC5: =DE_Calc_Compare!I57 -> 298.55 | AD5: =DE_Calc_Compare!I58 -> 293.3 | AE5: =DE_Calc_Compare!I59 -> 286.65 | AF5: =DE_Calc_Compare!I60 -> 278.6 | AG5: No HVAC / no EV
A6: Occupancy | B6: Someone always at home | C6: Someone always at home | D6: No heating or cooling system | E6: Medium | F6: No electric vehicle | G6: Mostly overnight | H6: =DE_Calc_Compare!H92 -> 3500 | I6: =DE_Calc_Compare!J94 -> 0.0789 | J6: =DE_Calc_Compare!J95 -> 0.0791 | K6: =DE_Calc_Compare!J96 -> 0.0773 | L6: =DE_Calc_Compare!J97 -> 0.0822 | M6: =DE_Calc_Compare!J98 -> 0.0839 | N6: =DE_Calc_Compare!J99 -> 0.0876 | O6: =DE_Calc_Compare!J100 -> 0.0917 | P6: =DE_Calc_Compare!J101 -> 0.0887 | Q6: =DE_Calc_Compare!J102 -> 0.0853 | R6: =DE_Calc_Compare!J103 -> 0.0838 | S6: =DE_Calc_Compare!J104 -> 0.0819 | T6: =DE_Calc_Compare!J105 -> 0.0796 | U6: =DE_Calc_Compare!I94 -> 276.15 | V6: =DE_Calc_Compare!I95 -> 276.85 | W6: =DE_Calc_Compare!I96 -> 270.55 | X6: =DE_Calc_Compare!I97 -> 287.7 | Y6: =DE_Calc_Compare!I98 -> 293.65 | Z6: =DE_Calc_Compare!I99 -> 306.6 | AA6: =DE_Calc_Compare!I100 -> 320.95 | AB6: =DE_Calc_Compare!I101 -> 310.45 | AC6: =DE_Calc_Compare!I102 -> 298.55 | AD6: =DE_Calc_Compare!I103 -> 293.3 | AE6: =DE_Calc_Compare!I104 -> 286.65 | AF6: =DE_Calc_Compare!I105 -> 278.6 | AG6: No HVAC / no EV
A7: Heating/Cooling System | B7: No heating or cooling system | C7: Mostly away during the day | D7: No heating or cooling system | E7: Medium | F7: No electric vehicle | G7: Mostly overnight | H7: =DE_Calc_Compare!H137 -> 3500 | I7: =DE_Calc_Compare!J139 -> 0.0789 | J7: =DE_Calc_Compare!J140 -> 0.0791 | K7: =DE_Calc_Compare!J141 -> 0.0773 | L7: =DE_Calc_Compare!J142 -> 0.0822 | M7: =DE_Calc_Compare!J143 -> 0.0839 | N7: =DE_Calc_Compare!J144 -> 0.0876 | O7: =DE_Calc_Compare!J145 -> 0.0917 | P7: =DE_Calc_Compare!J146 -> 0.0887 | Q7: =DE_Calc_Compare!J147 -> 0.0853 | R7: =DE_Calc_Compare!J148 -> 0.0838 | S7: =DE_Calc_Compare!J149 -> 0.0819 | T7: =DE_Calc_Compare!J150 -> 0.0796 | U7: =DE_Calc_Compare!I139 -> 276.15 | V7: =DE_Calc_Compare!I140 -> 276.85 | W7: =DE_Calc_Compare!I141 -> 270.55 | X7: =DE_Calc_Compare!I142 -> 287.7 | Y7: =DE_Calc_Compare!I143 -> 293.65 | Z7: =DE_Calc_Compare!I144 -> 306.6 | AA7: =DE_Calc_Compare!I145 -> 320.95 | AB7: =DE_Calc_Compare!I146 -> 310.45 | AC7: =DE_Calc_Compare!I147 -> 298.55 | AD7: =DE_Calc_Compare!I148 -> 293.3 | AE7: =DE_Calc_Compare!I149 -> 286.65 | AF7: =DE_Calc_Compare!I150 -> 278.6 | AG7: Occupancy fixed at Mostly away; no EV
A8: Heating/Cooling System | B8: Air conditioning | C8: Mostly away during the day | D8: Air conditioning | E8: Medium | F8: No electric vehicle | G8: Mostly overnight | H8: =DE_Calc_Compare!H182 -> 3500 | I8: =DE_Calc_Compare!J184 -> 0.07684067 | J8: =DE_Calc_Compare!J185 -> 0.07703545 | K8: =DE_Calc_Compare!J186 -> 0.075282431 | L8: =DE_Calc_Compare!J187 -> 0.080054538 | M8: =DE_Calc_Compare!J188 -> 0.081710168 | N8: =DE_Calc_Compare!J189 -> 0.093844955 | O8: =DE_Calc_Compare!J190 -> 0.098237242 | P8: =DE_Calc_Compare!J191 -> 0.095023374 | Q8: =DE_Calc_Compare!J192 -> 0.083073627 | R8: =DE_Calc_Compare!J193 -> 0.081612778 | S8: =DE_Calc_Compare!J194 -> 0.079762369 | T8: =DE_Calc_Compare!J195 -> 0.0775224 | U8: =DE_Calc_Compare!I184 -> 268.94235 | V8: =DE_Calc_Compare!I185 -> 269.62407 | W8: =DE_Calc_Compare!I186 -> 263.48851 | X8: =DE_Calc_Compare!I187 -> 280.19088 | Y8: =DE_Calc_Compare!I188 -> 285.98559 | Z8: =DE_Calc_Compare!I189 -> 328.45734 | AA8: =DE_Calc_Compare!I190 -> 343.83035 | AB8: =DE_Calc_Compare!I191 -> 332.58181 | AC8: =DE_Calc_Compare!I192 -> 290.75769 | AD8: =DE_Calc_Compare!I193 -> 285.64472 | AE8: =DE_Calc_Compare!I194 -> 279.16829 | AF8: =DE_Calc_Compare!I195 -> 271.3284 | AG8: Occupancy fixed at Mostly away; no EV
A9: Heating/Cooling System | B9: Electric heating | C9: Mostly away during the day | D9: Electric heating | E9: Medium | F9: No electric vehicle | G9: Mostly overnight | H9: =DE_Calc_Compare!H227 -> 6500 | I9: =DE_Calc_Compare!J229 -> 0.10975781 | J9: =DE_Calc_Compare!J230 -> 0.11003603 | K9: =DE_Calc_Compare!J231 -> 0.10753205 | L9: =DE_Calc_Compare!J232 -> 0.11434844 | M9: =DE_Calc_Compare!J233 -> 0.041659987 | N9: =DE_Calc_Compare!J234 -> 0.043497197 | O9: =DE_Calc_Compare!J235 -> 0.045533025 | P9: =DE_Calc_Compare!J236 -> 0.044043395 | Q9: =DE_Calc_Compare!J237 -> 0.042355148 | R9: =DE_Calc_Compare!J238 -> 0.1165742 | S9: =DE_Calc_Compare!J239 -> 0.11393111 | T9: =DE_Calc_Compare!J240 -> 0.11073158 | U9: =DE_Calc_Compare!I229 -> 713.42579 | V9: =DE_Calc_Compare!I230 -> 715.23422 | W9: =DE_Calc_Compare!I231 -> 698.95834 | X9: =DE_Calc_Compare!I232 -> 743.26489 | Y9: =DE_Calc_Compare!I233 -> 270.78992 | Z9: =DE_Calc_Compare!I234 -> 282.73178 | AA9: =DE_Calc_Compare!I235 -> 295.96466 | AB9: =DE_Calc_Compare!I236 -> 286.28207 | AC9: =DE_Calc_Compare!I237 -> 275.30846 | AD9: =DE_Calc_Compare!I238 -> 757.73233 | AE9: =DE_Calc_Compare!I239 -> 740.55224 | AF9: =DE_Calc_Compare!I240 -> 719.75529 | AG9: Occupancy fixed at Mostly away; no EV
A10: Heating/Cooling System | B10: Heat pump (heating & cooling) | C10: Mostly away during the day | D10: Heat pump (heating & cooling) | E10: Medium | F10: No electric vehicle | G10: Mostly overnight | H10: =DE_Calc_Compare!H272 -> 5500 | I10: =DE_Calc_Compare!J274 -> 0.08698663 | J10: =DE_Calc_Compare!J275 -> 0.087207128 | K10: =DE_Calc_Compare!J276 -> 0.085222643 | L10: =DE_Calc_Compare!J277 -> 0.090624854 | M10: =DE_Calc_Compare!J278 -> 0.04804711 | N10: =DE_Calc_Compare!J279 -> 0.092379255 | O10: =DE_Calc_Compare!J280 -> 0.096702941 | P10: =DE_Calc_Compare!J281 -> 0.093539268 | Q10: =DE_Calc_Compare!J282 -> 0.048848849 | R10: =DE_Calc_Compare!J283 -> 0.092388841 | S10: =DE_Calc_Compare!J284 -> 0.090294106 | T10: =DE_Calc_Compare!J285 -> 0.087758374 | U10: =DE_Calc_Compare!I274 -> 478.42646 | V10: =DE_Calc_Compare!I275 -> 479.63921 | W10: =DE_Calc_Compare!I276 -> 468.72453 | X10: =DE_Calc_Compare!I277 -> 498.4367 | Y10: =DE_Calc_Compare!I278 -> 264.2591 | Z10: =DE_Calc_Compare!I279 -> 508.0859 | AA10: =DE_Calc_Compare!I280 -> 531.86618 | AB10: =DE_Calc_Compare!I281 -> 514.46597 | AC10: =DE_Calc_Compare!I282 -> 268.66867 | AD10: =DE_Calc_Compare!I283 -> 508.13863 | AE10: =DE_Calc_Compare!I284 -> 496.61759 | AF10: =DE_Calc_Compare!I285 -> 482.67106 | AG10: Occupancy fixed at Mostly away; no EV
A11: Heating/Cooling Usage | B11: Heat pump - Low | C11: Mostly away during the day | D11: Heat pump (heating & cooling) | E11: Low | F11: No electric vehicle | G11: Mostly overnight | H11: =DE_Calc_Compare!H317 -> 4900 | I11: =DE_Calc_Compare!J319 -> 0.084885234 | J11: =DE_Calc_Compare!J320 -> 0.085100406 | K11: =DE_Calc_Compare!J321 -> 0.083163861 | L11: =DE_Calc_Compare!J322 -> 0.088435567 | M11: =DE_Calc_Compare!J323 -> 0.056620571 | N11: =DE_Calc_Compare!J324 -> 0.091627281 | O11: =DE_Calc_Compare!J325 -> 0.095915772 | P11: =DE_Calc_Compare!J326 -> 0.092777851 | Q11: =DE_Calc_Compare!J327 -> 0.057565372 | R11: =DE_Calc_Compare!J328 -> 0.090156941 | S11: =DE_Calc_Compare!J329 -> 0.08811281 | T11: =DE_Calc_Compare!J330 -> 0.085638335 | U11: =DE_Calc_Compare!I319 -> 415.93765 | V11: =DE_Calc_Compare!I320 -> 416.99199 | W11: =DE_Calc_Compare!I321 -> 407.50292 | X11: =DE_Calc_Compare!I322 -> 433.33428 | Y11: =DE_Calc_Compare!I323 -> 277.4408 | Z11: =DE_Calc_Compare!I324 -> 448.97367 | AA11: =DE_Calc_Compare!I325 -> 469.98728 | AB11: =DE_Calc_Compare!I326 -> 454.61147 | AC11: =DE_Calc_Compare!I327 -> 282.07032 | AD11: =DE_Calc_Compare!I328 -> 441.76901 | AE11: =DE_Calc_Compare!I329 -> 431.75277 | AF11: =DE_Calc_Compare!I330 -> 419.62784 | AG11: System fixed at Heat pump; no EV
A12: Heating/Cooling Usage | B12: Heat pump - Medium | C12: Mostly away during the day | D12: Heat pump (heating & cooling) | E12: Medium | F12: No electric vehicle | G12: Mostly overnight | H12: =DE_Calc_Compare!H362 -> 5500 | I12: =DE_Calc_Compare!J364 -> 0.08698663 | J12: =DE_Calc_Compare!J365 -> 0.087207128 | K12: =DE_Calc_Compare!J366 -> 0.085222643 | L12: =DE_Calc_Compare!J367 -> 0.090624854 | M12: =DE_Calc_Compare!J368 -> 0.04804711 | N12: =DE_Calc_Compare!J369 -> 0.092379255 | O12: =DE_Calc_Compare!J370 -> 0.096702941 | P12: =DE_Calc_Compare!J371 -> 0.093539268 | Q12: =DE_Calc_Compare!J372 -> 0.048848849 | R12: =DE_Calc_Compare!J373 -> 0.092388841 | S12: =DE_Calc_Compare!J374 -> 0.090294106 | T12: =DE_Calc_Compare!J375 -> 0.087758374 | U12: =DE_Calc_Compare!I364 -> 478.42646 | V12: =DE_Calc_Compare!I365 -> 479.63921 | W12: =DE_Calc_Compare!I366 -> 468.72453 | X12: =DE_Calc_Compare!I367 -> 498.4367 | Y12: =DE_Calc_Compare!I368 -> 264.2591 | Z12: =DE_Calc_Compare!I369 -> 508.0859 | AA12: =DE_Calc_Compare!I370 -> 531.86618 | AB12: =DE_Calc_Compare!I371 -> 514.46597 | AC12: =DE_Calc_Compare!I372 -> 268.66867 | AD12: =DE_Calc_Compare!I373 -> 508.13863 | AE12: =DE_Calc_Compare!I374 -> 496.61759 | AF12: =DE_Calc_Compare!I375 -> 482.67106 | AG12: System fixed at Heat pump; no EV
A13: Heating/Cooling Usage | B13: Heat pump - High | C13: Mostly away during the day | D13: Heat pump (heating & cooling) | E13: High | F13: No electric vehicle | G13: Mostly overnight | H13: =DE_Calc_Compare!H407 -> 6100 | I13: =DE_Calc_Compare!J409 -> 0.088389421 | J13: =DE_Calc_Compare!J410 -> 0.088613475 | K13: =DE_Calc_Compare!J411 -> 0.086596986 | L13: =DE_Calc_Compare!J412 -> 0.092086317 | M13: =DE_Calc_Compare!J413 -> 0.040307581 | N13: =DE_Calc_Compare!J414 -> 0.094210351 | O13: =DE_Calc_Compare!J415 -> 0.09861974 | P13: =DE_Calc_Compare!J416 -> 0.095393358 | Q13: =DE_Calc_Compare!J417 -> 0.040980175 | R13: =DE_Calc_Compare!J418 -> 0.093878751 | S13: =DE_Calc_Compare!J419 -> 0.091750235 | T13: =DE_Calc_Compare!J420 -> 0.089173611 | U13: =DE_Calc_Compare!I409 -> 539.17547 | V13: =DE_Calc_Compare!I410 -> 540.5422 | W13: =DE_Calc_Compare!I411 -> 528.24162 | X13: =DE_Calc_Compare!I412 -> 561.72653 | Y13: =DE_Calc_Compare!I413 -> 245.87625 | Z13: =DE_Calc_Compare!I414 -> 574.68314 | AA13: =DE_Calc_Compare!I415 -> 601.58041 | AB13: =DE_Calc_Compare!I416 -> 581.89948 | AC13: =DE_Calc_Compare!I417 -> 249.97907 | AD13: =DE_Calc_Compare!I418 -> 572.66038 | AE13: =DE_Calc_Compare!I419 -> 559.67643 | AF13: =DE_Calc_Compare!I420 -> 543.95902 | AG13: System fixed at Heat pump; no EV
A14: Heating/Cooling Usage | B14: Heat pump - Very high | C14: Mostly away during the day | D14: Heat pump (heating & cooling) | E14: Very high | F14: No electric vehicle | G14: Mostly overnight | H14: =DE_Calc_Compare!H452 -> 6700 | I14: =DE_Calc_Compare!J454 -> 0.089637016 | J14: =DE_Calc_Compare!J455 -> 0.089864233 | K14: =DE_Calc_Compare!J456 -> 0.087819282 | L14: =DE_Calc_Compare!J457 -> 0.093386093 | M14: =DE_Calc_Compare!J458 -> 0.03323049 | N14: =DE_Calc_Compare!J459 -> 0.095966626 | O14: =DE_Calc_Compare!J460 -> 0.10045821 | P14: =DE_Calc_Compare!J461 -> 0.097171686 | Q14: =DE_Calc_Compare!J462 -> 0.033784992 | R14: =DE_Calc_Compare!J463 -> 0.095203827 | S14: =DE_Calc_Compare!J464 -> 0.093045267 | T14: =DE_Calc_Compare!J465 -> 0.090432275 | U14: =DE_Calc_Compare!I454 -> 600.56801 | V14: =DE_Calc_Compare!I455 -> 602.09036 | W14: =DE_Calc_Compare!I456 -> 588.38919 | X14: =DE_Calc_Compare!I457 -> 625.68682 | Y14: =DE_Calc_Compare!I458 -> 222.64428 | Z14: =DE_Calc_Compare!I459 -> 642.97639 | AA14: =DE_Calc_Compare!I460 -> 673.07004 | AB14: =DE_Calc_Compare!I461 -> 651.0503 | AC14: =DE_Calc_Compare!I462 -> 226.35945 | AD14: =DE_Calc_Compare!I463 -> 637.86564 | AE14: =DE_Calc_Compare!I464 -> 623.40329 | AF14: =DE_Calc_Compare!I465 -> 605.89624 | AG14: System fixed at Heat pump; no EV
A15: EV Annual Driving | B15: No electric vehicle | C15: Mostly away during the day | D15: No heating or cooling system | E15: Medium | F15: No electric vehicle | G15: Mostly overnight | H15: =DE_Calc_Compare!H497 -> 3500 | I15: =DE_Calc_Compare!J499 -> 0.0789 | J15: =DE_Calc_Compare!J500 -> 0.0791 | K15: =DE_Calc_Compare!J501 -> 0.0773 | L15: =DE_Calc_Compare!J502 -> 0.0822 | M15: =DE_Calc_Compare!J503 -> 0.0839 | N15: =DE_Calc_Compare!J504 -> 0.0876 | O15: =DE_Calc_Compare!J505 -> 0.0917 | P15: =DE_Calc_Compare!J506 -> 0.0887 | Q15: =DE_Calc_Compare!J507 -> 0.0853 | R15: =DE_Calc_Compare!J508 -> 0.0838 | S15: =DE_Calc_Compare!J509 -> 0.0819 | T15: =DE_Calc_Compare!J510 -> 0.0796 | U15: =DE_Calc_Compare!I499 -> 276.15 | V15: =DE_Calc_Compare!I500 -> 276.85 | W15: =DE_Calc_Compare!I501 -> 270.55 | X15: =DE_Calc_Compare!I502 -> 287.7 | Y15: =DE_Calc_Compare!I503 -> 293.65 | Z15: =DE_Calc_Compare!I504 -> 306.6 | AA15: =DE_Calc_Compare!I505 -> 320.95 | AB15: =DE_Calc_Compare!I506 -> 310.45 | AC15: =DE_Calc_Compare!I507 -> 298.55 | AD15: =DE_Calc_Compare!I508 -> 293.3 | AE15: =DE_Calc_Compare!I509 -> 286.65 | AF15: =DE_Calc_Compare!I510 -> 278.6 | AG15: No HVAC; overnight charging
A16: EV Annual Driving | B16: 5,000 km | C16: Mostly away during the day | D16: No heating or cooling system | E16: Medium | F16: 5,000 km | G16: Mostly overnight | H16: =DE_Calc_Compare!H542 -> 4400 | I16: =DE_Calc_Compare!J544 -> 0.079806818 | J16: =DE_Calc_Compare!J545 -> 0.079965909 | K16: =DE_Calc_Compare!J546 -> 0.078534091 | L16: =DE_Calc_Compare!J547 -> 0.082431818 | M16: =DE_Calc_Compare!J548 -> 0.083784091 | N16: =DE_Calc_Compare!J549 -> 0.086727273 | O16: =DE_Calc_Compare!J550 -> 0.089988636 | P16: =DE_Calc_Compare!J551 -> 0.087602273 | Q16: =DE_Calc_Compare!J552 -> 0.084897727 | R16: =DE_Calc_Compare!J553 -> 0.083704545 | S16: =DE_Calc_Compare!J554 -> 0.082193182 | T16: =DE_Calc_Compare!J555 -> 0.080363636 | U16: =DE_Calc_Compare!I544 -> 351.15 | V16: =DE_Calc_Compare!I545 -> 351.85 | W16: =DE_Calc_Compare!I546 -> 345.55 | X16: =DE_Calc_Compare!I547 -> 362.7 | Y16: =DE_Calc_Compare!I548 -> 368.65 | Z16: =DE_Calc_Compare!I549 -> 381.6 | AA16: =DE_Calc_Compare!I550 -> 395.95 | AB16: =DE_Calc_Compare!I551 -> 385.45 | AC16: =DE_Calc_Compare!I552 -> 373.55 | AD16: =DE_Calc_Compare!I553 -> 368.3 | AE16: =DE_Calc_Compare!I554 -> 361.65 | AF16: =DE_Calc_Compare!I555 -> 353.6 | AG16: No HVAC; overnight charging
A17: EV Annual Driving | B17: 10,000 km | C17: Mostly away during the day | D17: No heating or cooling system | E17: Medium | F17: 10,000 km | G17: Mostly overnight | H17: =DE_Calc_Compare!H587 -> 5300 | I17: =DE_Calc_Compare!J589 -> 0.08040566 | J17: =DE_Calc_Compare!J590 -> 0.080537736 | K17: =DE_Calc_Compare!J591 -> 0.079349057 | L17: =DE_Calc_Compare!J592 -> 0.082584906 | M17: =DE_Calc_Compare!J593 -> 0.083707547 | N17: =DE_Calc_Compare!J594 -> 0.086150943 | O17: =DE_Calc_Compare!J595 -> 0.088858491 | P17: =DE_Calc_Compare!J596 -> 0.086877358 | Q17: =DE_Calc_Compare!J597 -> 0.084632075 | R17: =DE_Calc_Compare!J598 -> 0.083641509 | S17: =DE_Calc_Compare!J599 -> 0.082386792 | T17: =DE_Calc_Compare!J600 -> 0.080867925 | U17: =DE_Calc_Compare!I589 -> 426.15 | V17: =DE_Calc_Compare!I590 -> 426.85 | W17: =DE_Calc_Compare!I591 -> 420.55 | X17: =DE_Calc_Compare!I592 -> 437.7 | Y17: =DE_Calc_Compare!I593 -> 443.65 | Z17: =DE_Calc_Compare!I594 -> 456.6 | AA17: =DE_Calc_Compare!I595 -> 470.95 | AB17: =DE_Calc_Compare!I596 -> 460.45 | AC17: =DE_Calc_Compare!I597 -> 448.55 | AD17: =DE_Calc_Compare!I598 -> 443.3 | AE17: =DE_Calc_Compare!I599 -> 436.65 | AF17: =DE_Calc_Compare!I600 -> 428.6 | AG17: No HVAC; overnight charging
A18: EV Annual Driving | B18: 15,000 km | C18: Mostly away during the day | D18: No heating or cooling system | E18: Medium | F18: 15,000 km | G18: Mostly overnight | H18: =DE_Calc_Compare!H632 -> 6200 | I18: =DE_Calc_Compare!J634 -> 0.080830645 | J18: =DE_Calc_Compare!J635 -> 0.080943548 | K18: =DE_Calc_Compare!J636 -> 0.079927419 | L18: =DE_Calc_Compare!J637 -> 0.082693548 | M18: =DE_Calc_Compare!J638 -> 0.083653226 | N18: =DE_Calc_Compare!J639 -> 0.085741935 | O18: =DE_Calc_Compare!J640 -> 0.088056452 | P18: =DE_Calc_Compare!J641 -> 0.086362903 | Q18: =DE_Calc_Compare!J642 -> 0.084443548 | R18: =DE_Calc_Compare!J643 -> 0.083596774 | S18: =DE_Calc_Compare!J644 -> 0.082524194 | T18: =DE_Calc_Compare!J645 -> 0.081225806 | U18: =DE_Calc_Compare!I634 -> 501.15 | V18: =DE_Calc_Compare!I635 -> 501.85 | W18: =DE_Calc_Compare!I636 -> 495.55 | X18: =DE_Calc_Compare!I637 -> 512.7 | Y18: =DE_Calc_Compare!I638 -> 518.65 | Z18: =DE_Calc_Compare!I639 -> 531.6 | AA18: =DE_Calc_Compare!I640 -> 545.95 | AB18: =DE_Calc_Compare!I641 -> 535.45 | AC18: =DE_Calc_Compare!I642 -> 523.55 | AD18: =DE_Calc_Compare!I643 -> 518.3 | AE18: =DE_Calc_Compare!I644 -> 511.65 | AF18: =DE_Calc_Compare!I645 -> 503.6 | AG18: No HVAC; overnight charging
A19: EV Annual Driving | B19: 20,000 km | C19: Mostly away during the day | D19: No heating or cooling system | E19: Medium | F19: 20,000 km | G19: Mostly overnight | H19: =DE_Calc_Compare!H677 -> 7100 | I19: =DE_Calc_Compare!J679 -> 0.081147887 | J19: =DE_Calc_Compare!J680 -> 0.081246479 | K19: =DE_Calc_Compare!J681 -> 0.080359155 | L19: =DE_Calc_Compare!J682 -> 0.082774648 | M19: =DE_Calc_Compare!J683 -> 0.083612676 | N19: =DE_Calc_Compare!J684 -> 0.08543662 | O19: =DE_Calc_Compare!J685 -> 0.087457746 | P19: =DE_Calc_Compare!J686 -> 0.085978873 | Q19: =DE_Calc_Compare!J687 -> 0.084302817 | R19: =DE_Calc_Compare!J688 -> 0.08356338 | S19: =DE_Calc_Compare!J689 -> 0.082626761 | T19: =DE_Calc_Compare!J690 -> 0.081492958 | U19: =DE_Calc_Compare!I679 -> 576.15 | V19: =DE_Calc_Compare!I680 -> 576.85 | W19: =DE_Calc_Compare!I681 -> 570.55 | X19: =DE_Calc_Compare!I682 -> 587.7 | Y19: =DE_Calc_Compare!I683 -> 593.65 | Z19: =DE_Calc_Compare!I684 -> 606.6 | AA19: =DE_Calc_Compare!I685 -> 620.95 | AB19: =DE_Calc_Compare!I686 -> 610.45 | AC19: =DE_Calc_Compare!I687 -> 598.55 | AD19: =DE_Calc_Compare!I688 -> 593.3 | AE19: =DE_Calc_Compare!I689 -> 586.65 | AF19: =DE_Calc_Compare!I690 -> 578.6 | AG19: No HVAC; overnight charging
A20: EV Annual Driving | B20: 25,000+ km | C20: Mostly away during the day | D20: No heating or cooling system | E20: Medium | F20: 25,000+ km | G20: Mostly overnight | H20: =DE_Calc_Compare!H722 -> 8000 | I20: =DE_Calc_Compare!J724 -> 0.08139375 | J20: =DE_Calc_Compare!J725 -> 0.08148125 | K20: =DE_Calc_Compare!J726 -> 0.08069375 | L20: =DE_Calc_Compare!J727 -> 0.0828375 | M20: =DE_Calc_Compare!J728 -> 0.08358125 | N20: =DE_Calc_Compare!J729 -> 0.0852 | O20: =DE_Calc_Compare!J730 -> 0.08699375 | P20: =DE_Calc_Compare!J731 -> 0.08568125 | Q20: =DE_Calc_Compare!J732 -> 0.08419375 | R20: =DE_Calc_Compare!J733 -> 0.0835375 | S20: =DE_Calc_Compare!J734 -> 0.08270625 | T20: =DE_Calc_Compare!J735 -> 0.0817 | U20: =DE_Calc_Compare!I724 -> 651.15 | V20: =DE_Calc_Compare!I725 -> 651.85 | W20: =DE_Calc_Compare!I726 -> 645.55 | X20: =DE_Calc_Compare!I727 -> 662.7 | Y20: =DE_Calc_Compare!I728 -> 668.65 | Z20: =DE_Calc_Compare!I729 -> 681.6 | AA20: =DE_Calc_Compare!I730 -> 695.95 | AB20: =DE_Calc_Compare!I731 -> 685.45 | AC20: =DE_Calc_Compare!I732 -> 673.55 | AD20: =DE_Calc_Compare!I733 -> 668.3 | AE20: =DE_Calc_Compare!I734 -> 661.65 | AF20: =DE_Calc_Compare!I735 -> 653.6 | AG20: No HVAC; overnight charging
